{"uid":"7f1c1c7a3df3c927","name":"Issuer Reponse Approval Status","fullName":"tests.end2end.transactions.test_issuer_response.TestIssuerReponse#test_issuer_response_status","historyId":"d6246cd375bc686fc39eb69799a71a23","time":{"start":1660031742525,"stop":1660031742525,"duration":0},"status":"broken","statusMessage":"TimeoutError: Failed to login.","statusTrace":"page = <fw.pages.login_page.LoginPage object at 0x7f5a53318990>\nwait_duration = 5, fail_message = 'Failed to login.'\n\n    @contextmanager\n    def url_change(page, wait_duration=5, fail_message=''):\n        \"\"\"\n        context manager for url change driver wait to be used in tests when url change is expected\n        \"\"\"\n        current_url = page.driver.current_url\n        yield\n        try:\n>           WebDriverWait(page.driver, wait_duration).until(url_changed(current_url))\n\nutils/explicit_waits/custom_waits.py:30: \n_ _ _ _ _ _ _ _ _ _ _ _ _ _ _ _ _ _ _ _ _ _ _ _ _ _ _ _ _ _ _ _ _ _ _ _ _ _ _ _ \n\nself = <selenium.webdriver.support.wait.WebDriverWait (session=\"b4ac227fc8dd3c6c92fe7ea7fe9a08a7\")>\nmethod = <utils.explicit_waits.custom_waits.url_changed object at 0x7f5a53318410>\nmessage = ''\n\n    def until(self, method, message=''):\n        \"\"\"Calls the method provided with the driver as an argument until the \\\n        return value is not False.\"\"\"\n        screen = None\n        stacktrace = None\n    \n        end_time = time.time() + self._timeout\n        while True:\n            try:\n                value = method(self._driver)\n                if value:\n                    return value\n            except self._ignored_exceptions as exc:\n                screen = getattr(exc, 'screen', None)\n                stacktrace = getattr(exc, 'stacktrace', None)\n            time.sleep(self._poll)\n            if time.time() > end_time:\n                break\n>       raise TimeoutException(message, screen, stacktrace)\nE       selenium.common.exceptions.TimeoutException: Message:\n\n../../_tool/Python/3.7.13/x64/lib/python3.7/site-packages/selenium/webdriver/support/wait.py:80: TimeoutException\n\nDuring handling of the above exception, another exception occurred:\n\ncfg = <config.Config object at 0x7f5a5340d310>\nusers = <config.Credentials object at 0x7f5a5340dad0>\nbrowser = <selenium.webdriver.chrome.webdriver.WebDriver (session=\"b4ac227fc8dd3c6c92fe7ea7fe9a08a7\")>\n\n    @allure.step(\"UI Login\")\n    @pytest.fixture\n    def ui_login(cfg, users, browser):\n        \"\"\"\n        Logs in test to fraudwall and logs out after test\n        \"\"\"\n        browser.get(cfg.TEST_URL)\n        login_page = fw.pages.login_page.LoginPage(browser)\n        if login_page.get_current_url_route() == 'login':\n            login_page.enter_username(users.ADMIN.username)\n            login_page.enter_password(users.ADMIN.password)\n            time.sleep(2)\n            with url_change(login_page, fail_message=\"Failed to login.\"):\n>               landing_page = login_page.click_login()\n\ntests/conftest.py:192: \n_ _ _ _ _ _ _ _ _ _ _ _ _ _ _ _ _ _ _ _ _ _ _ _ _ _ _ _ _ _ _ _ _ _ _ _ _ _ _ _ \n../../_tool/Python/3.7.13/x64/lib/python3.7/contextlib.py:119: in __exit__\n    next(self.gen)\n_ _ _ _ _ _ _ _ _ _ _ _ _ _ _ _ _ _ _ _ _ _ _ _ _ _ _ _ _ _ _ _ _ _ _ _ _ _ _ _ \n\npage = <fw.pages.login_page.LoginPage object at 0x7f5a53318990>\nwait_duration = 5, fail_message = 'Failed to login.'\n\n    @contextmanager\n    def url_change(page, wait_duration=5, fail_message=''):\n        \"\"\"\n        context manager for url change driver wait to be used in tests when url change is expected\n        \"\"\"\n        current_url = page.driver.current_url\n        yield\n        try:\n            WebDriverWait(page.driver, wait_duration).until(url_changed(current_url))\n        except TimeoutException as te:\n            if fail_message:\n>               raise TimeoutError(fail_message)\nE               TimeoutError: Failed to login.\n\nutils/explicit_waits/custom_waits.py:33: TimeoutError","flaky":false,"newFailed":false,"newBroken":true,"newPassed":false,"retriesCount":0,"retriesStatusChange":false,"beforeStages":[{"name":"check_known_issues","time":{"start":1660031742526,"stop":1660031742526,"duration":0},"status":"passed","steps":[],"attachments":[],"parameters":[],"stepsCount":0,"attachmentsCount":0,"shouldDisplayMessage":false,"hasContent":false},{"name":"ui_login","time":{"start":1660031742526,"stop":1660031750059,"duration":7533},"status":"broken","statusMessage":"TimeoutError: Failed to login.\n","statusTrace":"  File \"/var/snap/amazon-ssm-agent/5656/actions-runner/_work/_tool/Python/3.7.13/x64/lib/python3.7/site-packages/pluggy/callers.py\", line 187, in _multicall\n    res = hook_impl.function(*args)\n  File \"/var/snap/amazon-ssm-agent/5656/actions-runner/_work/_tool/Python/3.7.13/x64/lib/python3.7/site-packages/_pytest/fixtures.py\", line 1126, in pytest_fixture_setup\n    result = call_fixture_func(fixturefunc, request, kwargs)\n  File \"/var/snap/amazon-ssm-agent/5656/actions-runner/_work/_tool/Python/3.7.13/x64/lib/python3.7/site-packages/_pytest/fixtures.py\", line 925, in call_fixture_func\n    fixture_result = next(generator)\n  File \"/var/snap/amazon-ssm-agent/5656/actions-runner/_work/test-fw-ci/test-fw-ci/tests/conftest.py\", line 192, in ui_login\n    landing_page = login_page.click_login()\n  File \"/var/snap/amazon-ssm-agent/5656/actions-runner/_work/_tool/Python/3.7.13/x64/lib/python3.7/contextlib.py\", line 119, in __exit__\n    next(self.gen)\n  File \"/var/snap/amazon-ssm-agent/5656/actions-runner/_work/test-fw-ci/test-fw-ci/utils/explicit_waits/custom_waits.py\", line 33, in url_change\n    raise TimeoutError(fail_message)\n","steps":[],"attachments":[],"parameters":[],"stepsCount":0,"attachmentsCount":0,"shouldDisplayMessage":true,"hasContent":true}],"afterStages":[],"labels":[{"name":"tag","value":"@pytest.mark.usefixtures('check_known_issues')"},{"name":"tag","value":"regression"},{"name":"parentSuite","value":"tests.end2end.transactions"},{"name":"suite","value":"test_issuer_response"},{"name":"subSuite","value":"TestIssuerReponse"},{"name":"host","value":"ip-10-20-30-10"},{"name":"thread","value":"10204-MainThread"},{"name":"framework","value":"pytest"},{"name":"language","value":"cpython3"},{"name":"package","value":"tests.end2end.transactions.test_issuer_response"},{"name":"resultFormat","value":"allure2"}],"parameters":[{"name":"browser","value":"'chrome'"},{"name":"issuer_response_type","value":"('0', 'icon-check')"}],"links":[],"hidden":false,"retry":false,"extra":{"severity":"normal","retries":[],"categories":[{"name":"Test defects","matchedStatuses":[],"flaky":false}],"history":{"statistic":{"failed":0,"broken":3,"skipped":0,"passed":3,"unknown":0,"total":6},"items":[{"uid":"cdc4bc86c1a24a03","reportUrl":"https://bowiegan-jp.github.io/test-fw-ci/35//#testresult/cdc4bc86c1a24a03","status":"passed","time":{"start":1660024157013,"stop":1660024188995,"duration":31982}},{"uid":"8b912b583d66eb40","reportUrl":"https://bowiegan-jp.github.io/test-fw-ci/1//#testresult/8b912b583d66eb40","status":"passed","time":{"start":1658484911888,"stop":1658484944733,"duration":32845}},{"uid":"7d97559d94adf1c6","reportUrl":"https://bowiegan-jp.github.io/test-fw-ci/34//#testresult/7d97559d94adf1c6","status":"passed","time":{"start":1658389377357,"stop":1658389450310,"duration":72953}},{"uid":"c6dc72e6ebcd76f0","reportUrl":"https://bowiegan-jp.github.io/test-fw-ci/32//#testresult/c6dc72e6ebcd76f0","status":"broken","statusDetails":"urllib3.exceptions.MaxRetryError: HTTPConnectionPool(host='127.0.0.1', port=39541): Max retries exceeded with url: /session/153edf670ef0b40e11c1d81d51e0fc9d/url (Caused by NewConnectionError('<urllib3.connection.HTTPConnection object at 0x7f80dd059ed0>: Failed to establish a new connection: [Errno 111] Connection refused'))","time":{"start":1658386859680,"stop":1658386859680,"duration":0}},{"uid":"b529fb07ba539dd","reportUrl":"https://bowiegan-jp.github.io/test-fw-ci/31//#testresult/b529fb07ba539dd","status":"broken","statusDetails":"requests.exceptions.SSLError: HTTPSConnectionPool(host='10.20.20.221', port=443): Max retries exceeded with url: /api/transaction (Caused by SSLError(SSLCertVerificationError(1, '[SSL: CERTIFICATE_VERIFY_FAILED] certificate verify failed: unable to get local issuer certificate (_ssl.c:1091)')))","time":{"start":1658386178358,"stop":1658386178383,"duration":25}}]},"tags":["@pytest.mark.usefixtures('check_known_issues')","regression"]},"source":"7f1c1c7a3df3c927.json","parameterValues":["'chrome'","('0', 'icon-check')"]}